Workbook

Sheet Overview
A1: MONTH: | B1: December | C1: Raw Materials Cost: | D1: =SUM(C6:C27,F6:F11) -> 1311.4615 | E1: DAYS THIS MONTH
A2: YEAR: | B2: 2025 | C2: Revenue: | D2: =SUMPRODUCT('Products (Demand)'!B2:B30,'Products (Demand)'!E2:E30) -> 11904 | E2: {=DAY(EOMONTH(DATE(B2, MATCH(B1, {"January","February","March","April","May","June","July","August","September","October","November","December"}, 0), 1), 0))} -> 31
A3: BATCHID: | B3: =MONTH(DATEVALUE(B1 & " 1")) & RIGHT(B2,2) -> 1225 | C3: Profit: | D3: =D2-D1 -> 10592.539
A5: Ingredients | B5: Required (g) | C5: COST$ | D5: Materials | E5: Required | F5: COST$ | G5: Production (TRAYS) | H5: Rounded
A6: Amaranth | B6: =IF($A6="","", SUMIF(Formulations!$B:$B, $A6, Formulations!E:E) ) -> 0 | C6: =(B6/Vlookup(A6,'Input Guide'!$A$2:$D$108,4,false))*vlookup(A6,'Input Guide'!$A$1:$B$143,2,false) -> 0 | D6: Bottles | E6: =SUM('Products (Demand)'!$E$2:$E$20) -> 501 | F6: =E6*VLOOKUP(D6,'Input Guide'!$A$1:$B$31,2,false) -> 230.46 | G6: =IF('Input Guide'!C2="","",B6/vlookup(A6,'Input Guide'!$A$1:$D$130,4,false)) -> 0 | H6: =CEILING(G6,1) -> 0
A7: Arugula | B7: =IF($A7="","", SUMIF(Formulations!$B:$B, $A7, Formulations!E:E) ) -> 0 | C7: =(B7/Vlookup(A7,'Input Guide'!$A$2:$D$108,4,false))*vlookup(A7,'Input Guide'!$A$1:$B$143,2,false) -> 0 | D7: Capsules | E7: =SUMPRODUCT('Products (Demand)'!C2:C16,'Products (Demand)'!E2:E16) -> 30060 | F7: =E7*VLOOKUP(D7,'Input Guide'!$A$1:$B$31,2,false) -> 462.924 | G7: =IF('Input Guide'!C3="","",B7/vlookup(A7,'Input Guide'!$A$1:$D$130,4,false)) -> 0 | H7: =CEILING(G7,1) -> 0
A8: Ashwagandha | B8: =IF($A8="","", SUMIF(Formulations!$B:$B, $A8, Formulations!E:E) ) -> 1014.3141 | C8: =(B8/Vlookup(A8,'Input Guide'!$A$2:$D$108,4,false))*vlookup(A8,'Input Guide'!$A$1:$B$143,2,false) -> 14.200398 | D8: Labels | E8: =SUM('Products (Demand)'!$E$2:$E$20) -> 501 | F8: =E8*VLOOKUP(D8,'Input Guide'!$A$1:$B$31,2,false) -> 5.01 | G8: =IF('Input Guide'!C4="","",B8/vlookup(A8,'Input Guide'!$A$1:$D$130,4,false)) | H8: =CEILING(G8,1) -> 0
A9: Basil | B9: =IF($A9="","", SUMIF(Formulations!$B:$B, $A9, Formulations!E:E) ) -> 0 | C9: =(B9/Vlookup(A9,'Input Guide'!$A$2:$D$108,4,false))*vlookup(A9,'Input Guide'!$A$1:$B$143,2,false) -> 0 | D9: Lids | E9: =SUM('Products (Demand)'!$E$2:$E$20) -> 501 | F9: =E9*VLOOKUP(D9,'Input Guide'!$A$1:$B$31,2,false) -> 55.11 | G9: =IF('Input Guide'!C5="","",B9/vlookup(A9,'Input Guide'!$A$1:$D$130,4,false)) -> 0 | H9: =CEILING(G9,1) -> 0
A10: Beet | B10: =IF($A10="","", SUMIF(Formulations!$B:$B, $A10, Formulations!E:E) ) -> 0 | C10: =(B10/Vlookup(A10,'Input Guide'!$A$2:$D$108,4,false))*vlookup(A10,'Input Guide'!$A$1:$B$143,2,false) -> 0 | D10: Seals | E10: =SUM('Products (Demand)'!$E$2:$E$20) -> 501 | F10: =E10*VLOOKUP(D10,'Input Guide'!$A$1:$B$31,2,false) -> 0 | G10: =IF('Input Guide'!C6="","",B10/vlookup(A10,'Input Guide'!$A$1:$D$130,4,false)) -> 0 | H10: =CEILING(G10,1) -> 0
A11: Bladder Wrack | B11: =IF($A11="","", SUMIF(Formulations!$B:$B, $A11, Formulations!E:E) ) -> 1076.1106 | C11: =(B11/Vlookup(A11,'Input Guide'!$A$2:$D$108,4,false))*vlookup(A11,'Input Guide'!$A$1:$B$143,2,false) -> 21.522211 | D11: Shrink Seals | E11: =SUM('Products (Demand)'!$E$2:$E$20) -> 501 | F11: =E11*VLOOKUP(D11,'Input Guide'!$A$1:$B$31,2,false) -> 0 | G11: =IF('Input Guide'!C7="","",B11/vlookup(A11,'Input Guide'!$A$1:$D$130,4,false)) | H11: =CEILING(G11,1) -> 0
A12: Broccoli | B12: =IF($A12="","", SUMIF(Formulations!$B:$B, $A12, Formulations!E:E) ) -> 4975.0799 | C12: =(B12/Vlookup(A12,'Input Guide'!$A$2:$D$108,4,false))*vlookup(A12,'Input Guide'!$A$1:$B$143,2,false) -> 183.93797 | G12: =IF('Input Guide'!C8="","",B12/vlookup(A12,'Input Guide'!$A$1:$D$130,4,false)) -> 191.60205 | H12: =CEILING(G12,1) -> 192
A13: Cabbage | B13: =IF($A13="","", SUMIF(Formulations!$B:$B, $A13, Formulations!E:E) ) -> 0 | C13: =(B13/Vlookup(A13,'Input Guide'!$A$2:$D$108,4,false))*vlookup(A13,'Input Guide'!$A$1:$B$143,2,false) -> 0 | G13: =IF('Input Guide'!C9="","",B13/vlookup(A13,'Input Guide'!$A$1:$D$130,4,false)) -> 0 | H13: =CEILING(G13,1) -> 0
A14: Cantaloupe | B14: =IF($A14="","", SUMIF(Formulations!$B:$B, $A14, Formulations!E:E) ) -> 0 | C14: =(B14/Vlookup(A14,'Input Guide'!$A$2:$D$108,4,false))*vlookup(A14,'Input Guide'!$A$1:$B$143,2,false) -> 0 | G14: =IF('Input Guide'!C10="","",B14/vlookup(A14,'Input Guide'!$A$1:$D$130,4,false)) -> 0 | H14: =CEILING(G14,1) -> 0
A15: Chaga 10:1 | B15: =IF($A15="","", SUMIF(Formulations!$B:$B, $A15, Formulations!E:E) ) -> 600 | C15: =(B15/Vlookup(A15,'Input Guide'!$A$2:$D$108,4,false))*vlookup(A15,'Input Guide'!$A$1:$B$143,2,false) -> 15.6 | G15: =IF('Input Guide'!C11="","",B15/vlookup(A15,'Input Guide'!$A$1:$D$130,4,false)) | H15: =CEILING(G15,1) -> 0
A16: Cordyceps 10:1 | B16: =IF($A16="","", SUMIF(Formulations!$B:$B, $A16, Formulations!E:E) ) -> 1800 | C16: =(B16/Vlookup(A16,'Input Guide'!$A$2:$D$108,4,false))*vlookup(A16,'Input Guide'!$A$1:$B$143,2,false) -> 88.2 | G16: =IF('Input Guide'!C12="","",B16/vlookup(A16,'Input Guide'!$A$1:$D$130,4,false)) | H16: =CEILING(G16,1) -> 0
A17: Kale | B17: =IF($A17="","", SUMIF(Formulations!$B:$B, $A17, Formulations!E:E) ) -> 0 | C17: =(B17/Vlookup(A17,'Input Guide'!$A$2:$D$108,4,false))*vlookup(A17,'Input Guide'!$A$1:$B$143,2,false) -> 0 | G17: =IF('Input Guide'!C13="","",B17/vlookup(A17,'Input Guide'!$A$1:$D$130,4,false)) -> 0 | H17: =CEILING(G17,1) -> 0
A18: Lion’s Mane 10:1 | B18: =IF($A18="","", SUMIF(Formulations!$B:$B, $A18, Formulations!E:E) ) -> 1641.0988 | C18: =(B18/Vlookup(A18,'Input Guide'!$A$2:$D$108,4,false))*vlookup(A18,'Input Guide'!$A$1:$B$143,2,false) -> 66.464501 | G18: =IF('Input Guide'!C14="","",B18/vlookup(A18,'Input Guide'!$A$1:$D$130,4,false)) | H18: =CEILING(G18,1) -> 0
A19: Mustard | B19: =IF($A19="","", SUMIF(Formulations!$B:$B, $A19, Formulations!E:E) ) -> 0 | C19: =(B19/Vlookup(A19,'Input Guide'!$A$2:$D$108,4,false))*vlookup(A19,'Input Guide'!$A$1:$B$143,2,false) -> 0 | G19: =IF('Input Guide'!C15="","",B19/vlookup(A19,'Input Guide'!$A$1:$D$130,4,false)) -> 0 | H19: =CEILING(G19,1) -> 0
A20: Pea | B20: =IF($A20="","", SUMIF(Formulations!$B:$B, $A20, Formulations!E:E) ) -> 0 | C20: =(B20/Vlookup(A20,'Input Guide'!$A$2:$D$108,4,false))*vlookup(A20,'Input Guide'!$A$1:$B$143,2,false) -> 0 | G20: =IF('Input Guide'!C16="","",B20/vlookup(A20,'Input Guide'!$A$1:$D$130,4,false)) -> 0 | H20: =CEILING(G20,1) -> 0
A21: Popcorn | B21: =IF($A21="","", SUMIF(Formulations!$B:$B, $A21, Formulations!E:E) ) -> 0 | C21: =(B21/Vlookup(A21,'Input Guide'!$A$2:$D$108,4,false))*vlookup(A21,'Input Guide'!$A$1:$B$143,2,false) -> 0 | G21: =IF('Input Guide'!C17="","",B21/vlookup(A21,'Input Guide'!$A$1:$D$130,4,false)) -> 0 | H21: =CEILING(G21,1) -> 0
A22: Purple Irish sea moss | B22: =IF($A22="","", SUMIF(Formulations!$B:$B, $A22, Formulations!E:E) ) -> 1076.1106 | C22: =(B22/Vlookup(A22,'Input Guide'!$A$2:$D$108,4,false))*vlookup(A22,'Input Guide'!$A$1:$B$143,2,false) -> 113.87614 | G22: =IF('Input Guide'!C18="","",B22/vlookup(A22,'Input Guide'!$A$1:$D$130,4,false)) | H22: =CEILING(G22,1) -> 0
A23: Radish | B23: =IF($A23="","", SUMIF(Formulations!$B:$B, $A23, Formulations!E:E) ) -> 0 | C23: =(B23/Vlookup(A23,'Input Guide'!$A$2:$D$108,4,false))*vlookup(A23,'Input Guide'!$A$1:$B$143,2,false) -> 0 | G23: =IF('Input Guide'!C19="","",B23/vlookup(A23,'Input Guide'!$A$1:$D$130,4,false)) -> 0 | H23: =CEILING(G23,1) -> 0
... A27: Wheatgrass | B27: =IF($A27="","", SUMIF(Formulations!$B:$B, $A27, Formulations!E:E) ) -> 0 | C27: =(B27/Vlookup(A27,'Input Guide'!$A$2:$D$108,4,false))*vlookup(A27,'Input Guide'!$A$1:$B$143,2,false) -> 0 | G27: =IF('Input Guide'!C23="","",B27/vlookup(A27,'Input Guide'!$A$1:$D$130,4,false)) -> 0 | H27: =CEILING(G27,1) -> 0
G28: =SUM(G6:G27) -> 191.60205 | H28: =CEILING(G28,1) -> 192

Sheet Tray Production Schedule
A1: Production Month | B1: =Overview!B1 -> December
A2: Year | B2: =Overview!B2 -> 2025
A3: Anchor Day | B3: 1
A4: Anchor Date | B4: {=DATE($B$2, MATCH($B$1, {"January","February","March","April","May","June","July","August","September","October","November","December"}, 0), $B$3)} -> 45992
A8: MICROGREEN | B8: TRAYS NEEDED | C8: YIELD/TRAY | D8: GROWTH DAYS | E8: TRAYS/FD RUN | F8: # RUNS NEEDED | G8: FIRST SOW DATE | H8: CUM RUNS
A9: Amaranth | B9: =VLOOKUP(A9,Overview!$A$6:$H$38,8,false) -> 0 | C9: =VLOOKUP(A9,'Input Guide'!$A$1:$C$41,3,false) -> 5.171 | D9: =VLOOKUP(A9,'Input Guide'!$A$1:$F$35,6,false) -> 8 | E9: ='FD Planner'!$B$16/(C9*28.35) -> 16.371318 | F9: =CEILING(B9/E9,1) -> 0 | G9: =IF(A9="","", $B$4 - D9) -> 45984 | H9: =F9 -> 0
A10: Arugula | B10: =VLOOKUP(A10,Overview!$A$6:$H$38,8,false) -> 0 | C10: =VLOOKUP(A10,'Input Guide'!$A$1:$C$41,3,false) -> 9.408 | D10: =VLOOKUP(A10,'Input Guide'!$A$1:$F$35,6,false) -> 8 | E10: ='FD Planner'!$B$16/(C10*28.35) -> 8.9983083 | F10: =CEILING(B10/E10,1) -> 0 | G10: =IF(A10="","", $B$4 - D10) -> 45984 | H10: =H9+F10 -> 0
A11: Basil | B11: =VLOOKUP(A11,Overview!$A$6:$H$38,8,false) -> 0 | C11: =VLOOKUP(A11,'Input Guide'!$A$1:$C$41,3,false) -> 3.956 | D11: =VLOOKUP(A11,'Input Guide'!$A$1:$F$35,6,false) -> 18 | E11: ='FD Planner'!$B$16/(C11*28.35) -> 21.399415 | F11: =CEILING(B11/E11,1) -> 0 | G11: =IF(A11="","", $B$4 - D11) -> 45974 | H11: =H10+F11 -> 0
A12: Beet | B12: =VLOOKUP(A12,Overview!$A$6:$H$38,8,false) -> 0 | C12: =VLOOKUP(A12,'Input Guide'!$A$1:$C$41,3,false) -> 2.539 | D12: =VLOOKUP(A12,'Input Guide'!$A$1:$F$35,6,false) -> 11 | E12: ='FD Planner'!$B$16/(C12*28.35) -> 33.342294 | F12: =CEILING(B12/E12,1) -> 0 | G12: =IF(A12="","", $B$4 - D12) -> 45981 | H12: =H11+F12 -> 0
A13: Broccoli | B13: =VLOOKUP(A13,Overview!$A$6:$H$38,8,false) -> 192 | C13: =VLOOKUP(A13,'Input Guide'!$A$1:$C$41,3,false) -> 9.159 | D13: =VLOOKUP(A13,'Input Guide'!$A$1:$F$35,6,false) -> 8 | E13: ='FD Planner'!$B$16/(C13*28.35) -> 9.2429397 | F13: =CEILING(B13/E13,1) -> 21 | G13: =IF(A13="","", $B$4 - D13) -> 45984 | H13: =H12+F13 -> 21
A14: Cabbage | B14: =VLOOKUP(A14,Overview!$A$6:$H$38,8,false) -> 0 | C14: =VLOOKUP(A14,'Input Guide'!$A$1:$C$41,3,false) -> 8.284 | D14: =VLOOKUP(A14,'Input Guide'!$A$1:$F$35,6,false) -> 8 | E14: ='FD Planner'!$B$16/(C14*28.35) -> 10.219228 | F14: =CEILING(B14/E14,1) -> 0 | G14: =IF(A14="","", $B$4 - D14) -> 45984 | H14: =H13+F14 -> 21
A15: Cantaloupe | B15: =VLOOKUP(A15,Overview!$A$6:$H$38,8,false) -> 0 | C15: =VLOOKUP(A15,'Input Guide'!$A$1:$C$41,3,false) -> 6.14 | D15: =VLOOKUP(A15,'Input Guide'!$A$1:$F$35,6,false) -> 13 | E15: ='FD Planner'!$B$16/(C15*28.35) -> 13.787636 | F15: =CEILING(B15/E15,1) -> 0 | G15: =IF(A15="","", $B$4 - D15) -> 45979 | H15: =H14+F15 -> 21
A16: Kale | B16: =VLOOKUP(A16,Overview!$A$6:$H$38,8,false) -> 0 | C16: =VLOOKUP(A16,'Input Guide'!$A$1:$C$41,3,false) -> 13 | D16: =VLOOKUP(A16,'Input Guide'!$A$1:$F$35,6,false) -> 8 | E16: ='FD Planner'!$B$16/(C16*28.35) -> 6.5120065 | F16: =CEILING(B16/E16,1) -> 0 | G16: =IF(A16="","", $B$4 - D16) -> 45984 | H16: =H15+F16 -> 21
A17: Mustard | B17: =VLOOKUP(A17,Overview!$A$6:$H$38,8,false) -> 0 | C17: =VLOOKUP(A17,'Input Guide'!$A$1:$C$41,3,false) -> 2.996 | D17: =VLOOKUP(A17,'Input Guide'!$A$1:$F$35,6,false) -> 8 | E17: ='FD Planner'!$B$16/(C17*28.35) -> 28.25637 | F17: =CEILING(B17/E17,1) -> 0 | G17: =IF(A17="","", $B$4 - D17) -> 45984 | H17: =H16+F17 -> 21
A18: Pea | B18: =VLOOKUP(A18,Overview!$A$6:$H$38,8,false) -> 0 | C18: =VLOOKUP(A18,'Input Guide'!$A$1:$C$41,3,false) -> 10.543 | D18: =VLOOKUP(A18,'Input Guide'!$A$1:$F$35,6,false) -> 11 | E18: ='FD Planner'!$B$16/(C18*28.35) -> 8.0296011 | F18: =CEILING(B18/E18,1) -> 0 | G18: =IF(A18="","", $B$4 - D18) -> 45981 | H18: =H17+F18 -> 21
A19: Popcorn | B19: =VLOOKUP(A19,Overview!$A$6:$H$38,8,false) -> 0 | C19: =VLOOKUP(A19,'Input Guide'!$A$1:$C$41,3,false) -> 6.22 | D19: =VLOOKUP(A19,'Input Guide'!$A$1:$F$35,6,false) -> 11 | E19: ='FD Planner'!$B$16/(C19*28.35) -> 13.610303 | F19: =CEILING(B19/E19,1) -> 0 | G19: =IF(A19="","", $B$4 - D19) -> 45981 | H19: =H18+F19 -> 21
A20: Radish | B20: =VLOOKUP(A20,Overview!$A$6:$H$38,8,false) -> 0 | C20: =VLOOKUP(A20,'Input Guide'!$A$1:$C$41,3,false) -> 13.686 | D20: =VLOOKUP(A20,'Input Guide'!$A$1:$F$35,6,false) -> 8 | E20: ='FD Planner'!$B$16/(C20*28.35) -> 6.1855973 | F20: =CEILING(B20/E20,1) -> 0 | G20: =IF(A20="","", $B$4 - D20) -> 45984 | H20: =H19+F20 -> 21
A21: Sunflower | B21: =VLOOKUP(A21,Overview!$A$6:$H$38,8,false) -> 0 | C21: =VLOOKUP(A21,'Input Guide'!$A$1:$C$41,3,false) -> 14.805 | D21: =VLOOKUP(A21,'Input Guide'!$A$1:$F$35,6,false) -> 10 | E21: ='FD Planner'!$B$16/(C21*28.35) -> 5.7180739 | F21: =CEILING(B21/E21,1) -> 0 | G21: =IF(A21="","", $B$4 - D21) -> 45982 | H21: =H20+F21 -> 21
... A23: Wheatgrass | B23: =VLOOKUP(A23,Overview!$A$6:$H$38,8,false) -> 0 | C23: =VLOOKUP(A23,'Input Guide'!$A$1:$C$41,3,false) -> 5 | D23: =VLOOKUP(A23,'Input Guide'!$A$1:$F$35,6,false) -> 8 | E23: ='FD Planner'!$B$16/(C23*28.35) -> 16.931217 | F23: =CEILING(B23/E23,1) -> 0 | G23: =IF(A23="","", $B$4 - D23) -> 45984 | H23: =H22+F23 -> 21
A25: MICROGREEN | B25: RUN # | C25: TRAYS THIS RUN | D25: SOWING DATE | E25: HARVEST DATE
A26: =IFERROR(__xludf.DUMMYFUNCTION("IF( ROW()-ROW($A$26)+1 > SUM($F$9:$F$23), """", INDEX( FILTER($A$9:$A$23, $F$9:$F$23>0), MATCH( ROW()-ROW($A$26)+1, FILTER($H$9:$H$23 - $F$9:$F$23 + 1, $F$9:$F$23>0), 1 ) ) ) "),"Broccoli") -> Broccoli | B26: =IF($A26="","", ROW()-ROW($A$26)+1) -> 1 | C26: =IF($A26="","", INT( VLOOKUP($A26, $A$9:$F$23, 2, FALSE) / VLOOKUP($A26, $A$9:$F$23, 6, FALSE) ) + IF( $B26 <= MOD( VLOOKUP($A26, $A$9:$F$23, 2, FALSE), VLOOKUP($A26, $A$9:$F$23, 6, FALSE) ), 1, 0 ) ) -> 10 | D26: =IF($A26="","", $E26 - VLOOKUP($A26, $A$9:$D$23, 4, FALSE) ) -> 45984 | E26: =IF($A26="","", $B$4 + ROUND( ( $B26 - 1 ) * ( DAY(EOMONTH($B$4,0)) / SUM($F$9:$F$23) ) ,0) ) -> 45992
A27: =IFERROR(__xludf.DUMMYFUNCTION("IF( ROW()-ROW($A$26)+1 > SUM($F$9:$F$23), """", INDEX( FILTER($A$9:$A$23, $F$9:$F$23>0), MATCH( ROW()-ROW($A$26)+1, FILTER($H$9:$H$23 - $F$9:$F$23 + 1, $F$9:$F$23>0), 1 ) ) ) "),"Broccoli") -> Broccoli | B27: =IF($A27="","", ROW()-ROW($A$26)+1) -> 2 | C27: =IF($A27="","", INT( VLOOKUP($A27, $A$9:$F$23, 2, FALSE) / VLOOKUP($A27, $A$9:$F$23, 6, FALSE) ) + IF( $B27 <= MOD( VLOOKUP($A27, $A$9:$F$23, 2, FALSE), VLOOKUP($A27, $A$9:$F$23, 6, FALSE) ), 1, 0 ) ) -> 10 | D27: =IF($A27="","", $E27 - VLOOKUP($A27, $A$9:$D$23, 4, FALSE) ) -> 45985 | E27: =IF($A27="","", $B$4 + ROUND( ( $B27 - 1 ) * ( DAY(EOMONTH($B$4,0)) / SUM($F$9:$F$23) ) ,0) ) -> 45993
A28: =IFERROR(__xludf.DUMMYFUNCTION("IF( ROW()-ROW($A$26)+1 > SUM($F$9:$F$23), """", INDEX( FILTER($A$9:$A$23, $F$9:$F$23>0), MATCH( ROW()-ROW($A$26)+1, FILTER($H$9:$H$23 - $F$9:$F$23 + 1, $F$9:$F$23>0), 1 ) ) ) "),"Broccoli") -> Broccoli | B28: =IF($A28="","", ROW()-ROW($A$26)+1) -> 3 | C28: =IF($A28="","", INT( VLOOKUP($A28, $A$9:$F$23, 2, FALSE) / VLOOKUP($A28, $A$9:$F$23, 6, FALSE) ) + IF( $B28 <= MOD( VLOOKUP($A28, $A$9:$F$23, 2, FALSE), VLOOKUP($A28, $A$9:$F$23, 6, FALSE) ), 1, 0 ) ) -> 10 | D28: =IF($A28="","", $E28 - VLOOKUP($A28, $A$9:$D$23, 4, FALSE) ) -> 45987 | E28: =IF($A28="","", $B$4 + ROUND( ( $B28 - 1 ) * ( DAY(EOMONTH($B$4,0)) / SUM($F$9:$F$23) ) ,0) ) -> 45995
A29: =IFERROR(__xludf.DUMMYFUNCTION("IF( ROW()-ROW($A$26)+1 > SUM($F$9:$F$23), """", INDEX( FILTER($A$9:$A$23, $F$9:$F$23>0), MATCH( ROW()-ROW($A$26)+1, FILTER($H$9:$H$23 - $F$9:$F$23 + 1, $F$9:$F$23>0), 1 ) ) ) "),"Broccoli") -> Broccoli | B29: =IF($A29="","", ROW()-ROW($A$26)+1) -> 4 | C29: =IF($A29="","", INT( VLOOKUP($A29, $A$9:$F$23, 2, FALSE) / VLOOKUP($A29, $A$9:$F$23, 6, FALSE) ) + IF( $B29 <= MOD( VLOOKUP($A29, $A$9:$F$23, 2, FALSE), VLOOKUP($A29, $A$9:$F$23, 6, FALSE) ), 1, 0 ) ) -> 9 | D29: =IF($A29="","", $E29 - VLOOKUP($A29, $A$9:$D$23, 4, FALSE) ) -> 45988 | E29: =IF($A29="","", $B$4 + ROUND( ( $B29 - 1 ) * ( DAY(EOMONTH($B$4,0)) / SUM($F$9:$F$23) ) ,0) ) -> 45996
A30: =IFERROR(__xludf.DUMMYFUNCTION("IF( ROW()-ROW($A$26)+1 > SUM($F$9:$F$23), """", INDEX( FILTER($A$9:$A$23, $F$9:$F$23>0), MATCH( ROW()-ROW($A$26)+1, FILTER($H$9:$H$23 - $F$9:$F$23 + 1, $F$9:$F$23>0), 1 ) ) ) "),"Broccoli") -> Broccoli | B30: =IF($A30="","", ROW()-ROW($A$26)+1) -> 5 | C30: =IF($A30="","", INT( VLOOKUP($A30, $A$9:$F$23, 2, FALSE) / VLOOKUP($A30, $A$9:$F$23, 6, FALSE) ) + IF( $B30 <= MOD( VLOOKUP($A30, $A$9:$F$23, 2, FALSE), VLOOKUP($A30, $A$9:$F$23, 6, FALSE) ), 1, 0 ) ) -> 9 | D30: =IF($A30="","", $E30 - VLOOKUP($A30, $A$9:$D$23, 4, FALSE) ) -> 45990 | E30: =IF($A30="","", $B$4 + ROUND( ( $B30 - 1 ) * ( DAY(EOMONTH($B$4,0)) / SUM($F$9:$F$23) ) ,0) ) -> 45998
A31: =IFERROR(__xludf.DUMMYFUNCTION("IF( ROW()-ROW($A$26)+1 > SUM($F$9:$F$23), """", INDEX( FILTER($A$9:$A$23, $F$9:$F$23>0), MATCH( ROW()-ROW($A$26)+1, FILTER($H$9:$H$23 - $F$9:$F$23 + 1, $F$9:$F$23>0), 1 ) ) ) "),"Broccoli") -> Broccoli | B31: =IF($A31="","", ROW()-ROW($A$26)+1) -> 6 | C31: =IF($A31="","", INT( VLOOKUP($A31, $A$9:$F$23, 2, FALSE) / VLOOKUP($A31, $A$9:$F$23, 6, FALSE) ) + IF( $B31 <= MOD( VLOOKUP($A31, $A$9:$F$23, 2, FALSE), VLOOKUP($A31, $A$9:$F$23, 6, FALSE) ), 1, 0 ) ) -> 9 | D31: =IF($A31="","", $E31 - VLOOKUP($A31, $A$9:$D$23, 4, FALSE) ) -> 45991 | E31: =IF($A31="","", $B$4 + ROUND( ( $B31 - 1 ) * ( DAY(EOMONTH($B$4,0)) / SUM($F$9:$F$23) ) ,0) ) -> 45999
A32: =IFERROR(__xludf.DUMMYFUNCTION("IF( ROW()-ROW($A$26)+1 > SUM($F$9:$F$23), """", INDEX( FILTER($A$9:$A$23, $F$9:$F$23>0), MATCH( ROW()-ROW($A$26)+1, FILTER($H$9:$H$23 - $F$9:$F$23 + 1, $F$9:$F$23>0), 1 ) ) ) "),"Broccoli") -> Broccoli | B32: =IF($A32="","", ROW()-ROW($A$26)+1) -> 7 | C32: =IF($A32="","", INT( VLOOKUP($A32, $A$9:$F$23, 2, FALSE) / VLOOKUP($A32, $A$9:$F$23, 6, FALSE) ) + IF( $B32 <= MOD( VLOOKUP($A32, $A$9:$F$23, 2, FALSE), VLOOKUP($A32, $A$9:$F$23, 6, FALSE) ), 1, 0 ) ) -> 9 | D32: =IF($A32="","", $E32 - VLOOKUP($A32, $A$9:$D$23, 4, FALSE) ) -> 45993 | E32: =IF($A32="","", $B$4 + ROUND( ( $B32 - 1 ) * ( DAY(EOMONTH($B$4,0)) / SUM($F$9:$F$23) ) ,0) ) -> 46001
A33: =IFERROR(__xludf.DUMMYFUNCTION("IF( ROW()-ROW($A$26)+1 > SUM($F$9:$F$23), """", INDEX( FILTER($A$9:$A$23, $F$9:$F$23>0), MATCH( ROW()-ROW($A$26)+1, FILTER($H$9:$H$23 - $F$9:$F$23 + 1, $F$9:$F$23>0), 1 ) ) ) "),"Broccoli") -> Broccoli | B33: =IF($A33="","", ROW()-ROW($A$26)+1) -> 8 | C33: =IF($A33="","", INT( VLOOKUP($A33, $A$9:$F$23, 2, FALSE) / VLOOKUP($A33, $A$9:$F$23, 6, FALSE) ) + IF( $B33 <= MOD( VLOOKUP($A33, $A$9:$F$23, 2, FALSE), VLOOKUP($A33, $A$9:$F$23, 6, FALSE) ), 1, 0 ) ) -> 9 | D33: =IF($A33="","", $E33 - VLOOKUP($A33, $A$9:$D$23, 4, FALSE) ) -> 45994 | E33: =IF($A33="","", $B$4 + ROUND( ( $B33 - 1 ) * ( DAY(EOMONTH($B$4,0)) / SUM($F$9:$F$23) ) ,0) ) -> 46002
A34: =IFERROR(__xludf.DUMMYFUNCTION("IF( ROW()-ROW($A$26)+1 > SUM($F$9:$F$23), """", INDEX( FILTER($A$9:$A$23, $F$9:$F$23>0), MATCH( ROW()-ROW($A$26)+1, FILTER($H$9:$H$23 - $F$9:$F$23 + 1, $F$9:$F$23>0), 1 ) ) ) "),"Broccoli") -> Broccoli | B34: =IF($A34="","", ROW()-ROW($A$26)+1) -> 9 | C34: =IF($A34="","", INT( VLOOKUP($A34, $A$9:$F$23, 2, FALSE) / VLOOKUP($A34, $A$9:$F$23, 6, FALSE) ) + IF( $B34 <= MOD( VLOOKUP($A34, $A$9:$F$23, 2, FALSE), VLOOKUP($A34, $A$9:$F$23, 6, FALSE) ), 1, 0 ) ) -> 9 | D34: =IF($A34="","", $E34 - VLOOKUP($A34, $A$9:$D$23, 4, FALSE) ) -> 45996 | E34: =IF($A34="","", $B$4 + ROUND( ( $B34 - 1 ) * ( DAY(EOMONTH($B$4,0)) / SUM($F$9:$F$23) ) ,0) ) -> 46004
A35: =IFERROR(__xludf.DUMMYFUNCTION("IF( ROW()-ROW($A$26)+1 > SUM($F$9:$F$23), """", INDEX( FILTER($A$9:$A$23, $F$9:$F$23>0), MATCH( ROW()-ROW($A$26)+1, FILTER($H$9:$H$23 - $F$9:$F$23 + 1, $F$9:$F$23>0), 1 ) ) ) "),"Broccoli") -> Broccoli | B35: =IF($A35="","", ROW()-ROW($A$26)+1) -> 10 | C35: =IF($A35="","", INT( VLOOKUP($A35, $A$9:$F$23, 2, FALSE) / VLOOKUP($A35, $A$9:$F$23, 6, FALSE) ) + IF( $B35 <= MOD( VLOOKUP($A35, $A$9:$F$23, 2, FALSE), VLOOKUP($A35, $A$9:$F$23, 6, FALSE) ), 1, 0 ) ) -> 9 | D35: =IF($A35="","", $E35 - VLOOKUP($A35, $A$9:$D$23, 4, FALSE) ) -> 45997 | E35: =IF($A35="","", $B$4 + ROUND( ( $B35 - 1 ) * ( DAY(EOMONTH($B$4,0)) / SUM($F$9:$F$23) ) ,0) ) -> 46005
A36: =IFERROR(__xludf.DUMMYFUNCTION("IF( ROW()-ROW($A$26)+1 > SUM($F$9:$F$23), """", INDEX( FILTER($A$9:$A$23, $F$9:$F$23>0), MATCH( ROW()-ROW($A$26)+1, FILTER($H$9:$H$23 - $F$9:$F$23 + 1, $F$9:$F$23>0), 1 ) ) ) "),"Broccoli") -> Broccoli | B36: =IF($A36="","", ROW()-ROW($A$26)+1) -> 11 | C36: =IF($A36="","", INT( VLOOKUP($A36, $A$9:$F$23, 2, FALSE) / VLOOKUP($A36, $A$9:$F$23, 6, FALSE) ) + IF( $B36 <= MOD( VLOOKUP($A36, $A$9:$F$23, 2, FALSE), VLOOKUP($A36, $A$9:$F$23, 6, FALSE) ), 1, 0 ) ) -> 9 | D36: =IF($A36="","", $E36 - VLOOKUP($A36, $A$9:$D$23, 4, FALSE) ) -> 45999 | E36: =IF($A36="","", $B$4 + ROUND( ( $B36 - 1 ) * ( DAY(EOMONTH($B$4,0)) / SUM($F$9:$F$23) ) ,0) ) -> 46007
A37: =IFERROR(__xludf.DUMMYFUNCTION("IF( ROW()-ROW($A$26)+1 > SUM($F$9:$F$23), """", INDEX( FILTER($A$9:$A$23, $F$9:$F$23>0), MATCH( ROW()-ROW($A$26)+1, FILTER($H$9:$H$23 - $F$9:$F$23 + 1, $F$9:$F$23>0), 1 ) ) ) "),"Broccoli") -> Broccoli | B37: =IF($A37="","", ROW()-ROW($A$26)+1) -> 12 | C37: =IF($A37="","", INT( VLOOKUP($A37, $A$9:$F$23, 2, FALSE) / VLOOKUP($A37, $A$9:$F$23, 6, FALSE) ) + IF( $B37 <= MOD( VLOOKUP($A37, $A$9:$F$23, 2, FALSE), VLOOKUP($A37, $A$9:$F$23, 6, FALSE) ), 1, 0 ) ) -> 9 | D37: =IF($A37="","", $E37 - VLOOKUP($A37, $A$9:$D$23, 4, FALSE) ) -> 46000 | E37: =IF($A37="","", $B$4 + ROUND( ( $B37 - 1 ) * ( DAY(EOMONTH($B$4,0)) / SUM($F$9:$F$23) ) ,0) ) -> 46008
... A46: =IFERROR(__xludf.DUMMYFUNCTION("IF( ROW()-ROW($A$26)+1 > SUM($F$9:$F$23), """", INDEX( FILTER($A$9:$A$23, $F$9:$F$23>0), MATCH( ROW()-ROW($A$26)+1, FILTER($H$9:$H$23 - $F$9:$F$23 + 1, $F$9:$F$23>0), 1 ) ) ) "),"Broccoli") -> Broccoli | B46: =IF($A46="","", ROW()-ROW($A$26)+1) -> 21 | C46: =IF($A46="","", INT( VLOOKUP($A46, $A$9:$F$23, 2, FALSE) / VLOOKUP($A46, $A$9:$F$23, 6, FALSE) ) + IF( $B46 <= MOD( VLOOKUP($A46, $A$9:$F$23, 2, FALSE), VLOOKUP($A46, $A$9:$F$23, 6, FALSE) ), 1, 0 ) ) -> 9 | D46: =IF($A46="","", $E46 - VLOOKUP($A46, $A$9:$D$23, 4, FALSE) ) -> 46014 | E46: =IF($A46="","", $B$4 + ROUND( ( $B46 - 1 ) * ( DAY(EOMONTH($B$4,0)) / SUM($F$9:$F$23) ) ,0) ) -> 46022
B47: =IF($A47="","", ROW()-ROW($A$26)+1) | C47: =IF($A47="","", INT( VLOOKUP($A47, $A$9:$F$23, 2, FALSE) / VLOOKUP($A47, $A$9:$F$23, 6, FALSE) ) + IF( $B47 <= MOD( VLOOKUP($A47, $A$9:$F$23, 2, FALSE), VLOOKUP($A47, $A$9:$F$23, 6, FALSE) ), 1, 0 ) ) | D47: =IF($A47="","", $E47 - VLOOKUP($A47, $A$9:$D$23, 4, FALSE) ) | E47: =IF($A47="","", $B$4 + ROUND( ( $B47 - 1 ) * ( DAY(EOMONTH($B$4,0)) / SUM($F$9:$F$23) ) ,0) )
B48: =IF($A48="","", ROW()-ROW($A$26)+1) | C48: =IF($A48="","", INT( VLOOKUP($A48, $A$9:$F$23, 2, FALSE) / VLOOKUP($A48, $A$9:$F$23, 6, FALSE) ) + IF( $B48 <= MOD( VLOOKUP($A48, $A$9:$F$23, 2, FALSE), VLOOKUP($A48, $A$9:$F$23, 6, FALSE) ), 1, 0 ) ) | D48: =IF($A48="","", $E48 - VLOOKUP($A48, $A$9:$D$23, 4, FALSE) ) | E48: =IF($A48="","", $B$4 + ROUND( ( $B48 - 1 ) * ( DAY(EOMONTH($B$4,0)) / SUM($F$9:$F$23) ) ,0) )
B49: =IF($A49="","", ROW()-ROW($A$26)+1) | C49: =IF($A49="","", INT( VLOOKUP($A49, $A$9:$F$23, 2, FALSE) / VLOOKUP($A49, $A$9:$F$23, 6, FALSE) ) + IF( $B49 <= MOD( VLOOKUP($A49, $A$9:$F$23, 2, FALSE), VLOOKUP($A49, $A$9:$F$23, 6, FALSE) ), 1, 0 ) ) | D49: =IF($A49="","", $E49 - VLOOKUP($A49, $A$9:$D$23, 4, FALSE) ) | E49: =IF($A49="","", $B$4 + ROUND( ( $B49 - 1 ) * ( DAY(EOMONTH($B$4,0)) / SUM($F$9:$F$23) ) ,0) )
B50: =IF($A50="","", ROW()-ROW($A$26)+1) | C50: =IF($A50="","", INT( VLOOKUP($A50, $A$9:$F$23, 2, FALSE) / VLOOKUP($A50, $A$9:$F$23, 6, FALSE) ) + IF( $B50 <= MOD( VLOOKUP($A50, $A$9:$F$23, 2, FALSE), VLOOKUP($A50, $A$9:$F$23, 6, FALSE) ), 1, 0 ) ) | D50: =IF($A50="","", $E50 - VLOOKUP($A50, $A$9:$D$23, 4, FALSE) ) | E50: =IF($A50="","", $B$4 + ROUND( ( $B50 - 1 ) * ( DAY(EOMONTH($B$4,0)) / SUM($F$9:$F$23) ) ,0) )
B51: =IF($A51="","", ROW()-ROW($A$26)+1) | C51: =IF($A51="","", INT( VLOOKUP($A51, $A$9:$F$23, 2, FALSE) / VLOOKUP($A51, $A$9:$F$23, 6, FALSE) ) + IF( $B51 <= MOD( VLOOKUP($A51, $A$9:$F$23, 2, FALSE), VLOOKUP($A51, $A$9:$F$23, 6, FALSE) ), 1, 0 ) ) | D51: =IF($A51="","", $E51 - VLOOKUP($A51, $A$9:$D$23, 4, FALSE) ) | E51: =IF($A51="","", $B$4 + ROUND( ( $B51 - 1 ) * ( DAY(EOMONTH($B$4,0)) / SUM($F$9:$F$23) ) ,0) )
B52: =IF($A52="","", ROW()-ROW($A$26)+1) | C52: =IF($A52="","", INT( VLOOKUP($A52, $A$9:$F$23, 2, FALSE) / VLOOKUP($A52, $A$9:$F$23, 6, FALSE) ) + IF( $B52 <= MOD( VLOOKUP($A52, $A$9:$F$23, 2, FALSE), VLOOKUP($A52, $A$9:$F$23, 6, FALSE) ), 1, 0 ) ) | D52: =IF($A52="","", $E52 - VLOOKUP($A52, $A$9:$D$23, 4, FALSE) ) | E52: =IF($A52="","", $B$4 + ROUND( ( $B52 - 1 ) * ( DAY(EOMONTH($B$4,0)) / SUM($F$9:$F$23) ) ,0) )
B53: =IF($A53="","", ROW()-ROW($A$26)+1) | C53: =IF($A53="","", INT( VLOOKUP($A53, $A$9:$F$23, 2, FALSE) / VLOOKUP($A53, $A$9:$F$23, 6, FALSE) ) + IF( $B53 <= MOD( VLOOKUP($A53, $A$9:$F$23, 2, FALSE), VLOOKUP($A53, $A$9:$F$23, 6, FALSE) ), 1, 0 ) ) | D53: =IF($A53="","", $E53 - VLOOKUP($A53, $A$9:$D$23, 4, FALSE) ) | E53: =IF($A53="","", $B$4 + ROUND( ( $B53 - 1 ) * ( DAY(EOMONTH($B$4,0)) / SUM($F$9:$F$23) ) ,0) )
...

Sheet Products (Demand)
A1: PRODUCT | B1: SELL PRICE | C1: CAPSULES PER BOTTLE | D1: CAPSULE FILL (g) | E1: UNITS TO MAKE | F1: TOTAL POWDER (g)
A2: Broccoli | B2: 22 | C2: 60 | D2: =SUMIF(Formulations!A2:A12,A2,Formulations!C2:C12) -> 0.4 | E2: 154 | F2: =IF(A2="","",C2*D2*E2) -> 3696
A3: Mushroom | B3: 22 | C3: 60 | D3: =SUMIF(Formulations!A3:A13,A3,Formulations!C3:C13) -> 0.4 | E3: 200 | F3: =IF(A3="","",C3*D3*E3) -> 4800
A4: Complete102+ | B4: 28 | C4: 60 | D4: =SUMIF(Formulations!A4:A14,A4,Formulations!C4:C14) -> 0.604 | E4: 147 | F4: =IF(A4="","",C4*D4*E4) -> 5327.28

Sheet Formulations
A1: PRODUCT | B1: INGREDIENT | C1: GRAMS NEEDED | D1: PERCENT OF FORMULA | E1: GRAMS NEEDED FOR BATCH
A2: Broccoli | B2: Broccoli | C2: 0.4 | D2: =C2/vlookup(A2,'Products (Demand)'!$A$2:$D$20,4,false) -> 1 | E2: {=IF(OR($A2="",$B2="",$D2=""),"", LET( pct, IF(RIGHT($D2,1)="%", VALUE(SUBSTITUTE($D2,"%",""))/100, $D2), capFill, XLOOKUP($A2, 'Products (Demand)'!$A:$A, 'Products (Demand)'!$D:$D, 0), capsPer, XLOOKUP($A2, 'Products (Demand)'!$A:$A, 'Products (Demand)'!$C:$C, 0), units, XLOOKUP($A2, 'Products (Demand)'!$A:$A, 'Products (Demand)'!$E:$E, 0), pct * capFill * capsPer * units ) )} -> 3696
A3: Mushroom | B3: Lion’s Mane 10:1 | C3: 0.1 | D3: =C3/vlookup(A3,'Products (Demand)'!$A$2:$D$20,4,false) -> 0.25 | E3: {=IF(OR($A3="",$B3="",$D3=""),"", LET( pct, IF(RIGHT($D3,1)="%", VALUE(SUBSTITUTE($D3,"%",""))/100, $D3), capFill, XLOOKUP($A3, 'Products (Demand)'!$A:$A, 'Products (Demand)'!$D:$D, 0), capsPer, XLOOKUP($A3, 'Products (Demand)'!$A:$A, 'Products (Demand)'!$C:$C, 0), units, XLOOKUP($A3, 'Products (Demand)'!$A:$A, 'Products (Demand)'!$E:$E, 0), pct * capFill * capsPer * units ) )} -> 1200
A4: Mushroom | B4: Reishi 10:1 | C4: 0.1 | D4: =C4/vlookup(A4,'Products (Demand)'!$A$2:$D$20,4,false) -> 0.25 | E4: {=IF(OR($A4="",$B4="",$D4=""),"", LET( pct, IF(RIGHT($D4,1)="%", VALUE(SUBSTITUTE($D4,"%",""))/100, $D4), capFill, XLOOKUP($A4, 'Products (Demand)'!$A:$A, 'Products (Demand)'!$D:$D, 0), capsPer, XLOOKUP($A4, 'Products (Demand)'!$A:$A, 'Products (Demand)'!$C:$C, 0), units, XLOOKUP($A4, 'Products (Demand)'!$A:$A, 'Products (Demand)'!$E:$E, 0), pct * capFill * capsPer * units ) )} -> 1200
A5: Mushroom | B5: Cordyceps 10:1 | C5: 0.15 | D5: =C5/vlookup(A5,'Products (Demand)'!$A$2:$D$20,4,false) -> 0.375 | E5: {=IF(OR($A5="",$B5="",$D5=""),"", LET( pct, IF(RIGHT($D5,1)="%", VALUE(SUBSTITUTE($D5,"%",""))/100, $D5), capFill, XLOOKUP($A5, 'Products (Demand)'!$A:$A, 'Products (Demand)'!$D:$D, 0), capsPer, XLOOKUP($A5, 'Products (Demand)'!$A:$A, 'Products (Demand)'!$C:$C, 0), units, XLOOKUP($A5, 'Products (Demand)'!$A:$A, 'Products (Demand)'!$E:$E, 0), pct * capFill * capsPer * units ) )} -> 1800
A6: Mushroom | B6: Chaga 10:1 | C6: 0.05 | D6: =C6/vlookup(A6,'Products (Demand)'!$A$2:$D$20,4,false) -> 0.125 | E6: {=IF(OR($A6="",$B6="",$D6=""),"", LET( pct, IF(RIGHT($D6,1)="%", VALUE(SUBSTITUTE($D6,"%",""))/100, $D6), capFill, XLOOKUP($A6, 'Products (Demand)'!$A:$A, 'Products (Demand)'!$D:$D, 0), capsPer, XLOOKUP($A6, 'Products (Demand)'!$A:$A, 'Products (Demand)'!$C:$C, 0), units, XLOOKUP($A6, 'Products (Demand)'!$A:$A, 'Products (Demand)'!$E:$E, 0), pct * capFill * capsPer * units ) )} -> 600
A7: Complete102+ | B7: Purple Irish Sea Moss | C7: 0.122 | D7: =C7/vlookup(A7,'Products (Demand)'!$A$2:$D$20,4,false) -> 0.20198675 | E7: {=IF(OR($A7="",$B7="",$D7=""),"", LET( pct, IF(RIGHT($D7,1)="%", VALUE(SUBSTITUTE($D7,"%",""))/100, $D7), capFill, XLOOKUP($A7, 'Products (Demand)'!$A:$A, 'Products (Demand)'!$D:$D, 0), capsPer, XLOOKUP($A7, 'Products (Demand)'!$A:$A, 'Products (Demand)'!$C:$C, 0), units, XLOOKUP($A7, 'Products (Demand)'!$A:$A, 'Products (Demand)'!$E:$E, 0), pct * capFill * capsPer * units ) )} -> 1076.1106
A8: Complete102+ | B8: Bladder Wrack | C8: 0.122 | D8: =C8/vlookup(A8,'Products (Demand)'!$A$2:$D$20,4,false) -> 0.20198675 | E8: {=IF(OR($A8="",$B8="",$D8=""),"", LET( pct, IF(RIGHT($D8,1)="%", VALUE(SUBSTITUTE($D8,"%",""))/100, $D8), capFill, XLOOKUP($A8, 'Products (Demand)'!$A:$A, 'Products (Demand)'!$D:$D, 0), capsPer, XLOOKUP($A8, 'Products (Demand)'!$A:$A, 'Products (Demand)'!$C:$C, 0), units, XLOOKUP($A8, 'Products (Demand)'!$A:$A, 'Products (Demand)'!$E:$E, 0), pct * capFill * capsPer * units ) )} -> 1076.1106
A9: Complete102+ | B9: Broccoli | C9: 0.145 | D9: =C9/vlookup(A9,'Products (Demand)'!$A$2:$D$20,4,false) -> 0.24006623 | E9: {=IF(OR($A9="",$B9="",$D9=""),"", LET( pct, IF(RIGHT($D9,1)="%", VALUE(SUBSTITUTE($D9,"%",""))/100, $D9), capFill, XLOOKUP($A9, 'Products (Demand)'!$A:$A, 'Products (Demand)'!$D:$D, 0), capsPer, XLOOKUP($A9, 'Products (Demand)'!$A:$A, 'Products (Demand)'!$C:$C, 0), units, XLOOKUP($A9, 'Products (Demand)'!$A:$A, 'Products (Demand)'!$E:$E, 0), pct * capFill * capsPer * units ) )} -> 1279.0799
A10: Complete102+ | B10: Lion’s Mane 10:1 | C10: 0.05 | D10: =C10/vlookup(A10,'Products (Demand)'!$A$2:$D$20,4,false) -> 0.082781457 | E10: {=IF(OR($A10="",$B10="",$D10=""),"", LET( pct, IF(RIGHT($D10,1)="%", VALUE(SUBSTITUTE($D10,"%",""))/100, $D10), capFill, XLOOKUP($A10, 'Products (Demand)'!$A:$A, 'Products (Demand)'!$D:$D, 0), capsPer, XLOOKUP($A10, 'Products (Demand)'!$A:$A, 'Products (Demand)'!$C:$C, 0), units, XLOOKUP($A10, 'Products (Demand)'!$A:$A, 'Products (Demand)'!$E:$E, 0), pct * capFill * capsPer * units ) )} -> 441.09878
A11: Complete102+ | B11: Reishi 10:1 | C11: 0.05 | D11: =C11/vlookup(A11,'Products (Demand)'!$A$2:$D$20,4,false) -> 0.082781457 | E11: {=IF(OR($A11="",$B11="",$D11=""),"", LET( pct, IF(RIGHT($D11,1)="%", VALUE(SUBSTITUTE($D11,"%",""))/100, $D11), capFill, XLOOKUP($A11, 'Products (Demand)'!$A:$A, 'Products (Demand)'!$D:$D, 0), capsPer, XLOOKUP($A11, 'Products (Demand)'!$A:$A, 'Products (Demand)'!$C:$C, 0), units, XLOOKUP($A11, 'Products (Demand)'!$A:$A, 'Products (Demand)'!$E:$E, 0), pct * capFill * capsPer * units ) )} -> 441.09878
A12: Complete102+ | B12: Ashwagandha | C12: 0.115 | D12: =C12/vlookup(A12,'Products (Demand)'!$A$2:$D$20,4,false) -> 0.19039735 | E12: {=IF(OR($A12="",$B12="",$D12=""),"", LET( pct, IF(RIGHT($D12,1)="%", VALUE(SUBSTITUTE($D12,"%",""))/100, $D12), capFill, XLOOKUP($A12, 'Products (Demand)'!$A:$A, 'Products (Demand)'!$D:$D, 0), capsPer, XLOOKUP($A12, 'Products (Demand)'!$A:$A, 'Products (Demand)'!$C:$C, 0), units, XLOOKUP($A12, 'Products (Demand)'!$A:$A, 'Products (Demand)'!$E:$E, 0), pct * capFill * capsPer * units ) )} -> 1014.3141

Sheet Input Guide
A1: INPUT | B1: COST/UNIT | C1: FRESH YIELD (oz) | D1: DRIED WEIGHT (g) | E1: SOW RATE(g) | F1: Growth Days
A2: Amaranth | B2: 1.11 | C2: 5.171 | D2: 14.6601 | E2: 15 | F2: 8
A3: Arugula | B3: 1.1 | C3: 9.408 | D3: 26.671444 | E3: 25 | F3: 8
A4: Ashwagandha | B4: 14 | D4: 1000
A5: Basil | B5: 1.06 | C5: 3.956 | D5: 11.216155 | E5: 15 | F5: 18
A6: Beet | B6: 1.7 | C6: 2.539 | D6: 7.198875 | E6: 40 | F6: 11
A7: Bladder Wrack | B7: 20 | D7: 1000
A8: Broccoli | B8: 0.96 | C8: 9.159 | D8: 25.965692 | E8: 25 | F8: 8
A9: Cabbage | B9: 1.2 | C9: 8.284 | D9: 23.486203 | E9: 25 | F9: 8
A10: Cantaloupe | B10: 1.1 | C10: 6.14 | D10: 17.4069 | E10: 30 | F10: 13
A11: Chaga 10:1 | B11: 26 | D11: 1000
A12: Cordyceps 10:1 | B12: 49 | D12: 1000
A13: Kale | B13: 1.08 | C13: 13 | D13: 36.855 | E13: 25 | F13: 8
A14: Lion’s Mane 10:1 | B14: 40.5 | D14: 1000
A15: Mustard | B15: 0.8 | C15: 2.996 | D15: 8.4924 | E15: 25 | F15: 8
A16: Pea | B16: 1.83 | C16: 10.543 | D16: 29.89035 | E16: 250 | F16: 11
A17: Popcorn | B17: 2.82 | C17: 6.22 | D17: 17.6337 | E17: 150 | F17: 11
A18: Purple Irish sea moss | B18: 240 | D18: 2267.96
A19: Radish | B19: 2.15 | C19: 13.686 | D19: 38.800841 | E19: 55 | F19: 8
A20: Reishi 10:1 | B20: 33 | D20: 1000
A21: Sunflower | B21: 1.69 | C21: 14.805 | D21: 41.972175 | E21: 150 | F21: 10
A22: Upland Cress | B22: 1 | C22: 6 | D22: 17.01 | E22: 30 | F22: 8
A23: Wheatgrass | B23: 1.85 | C23: 5 | D23: 14.175 | E23: 200 | F23: 8
A24: Bottles | B24: 0.46
A25: Capsules | B25: 0.0154
A26: Labels | B26: 0.01
A27: Lids | B27: 0.11
A28: Seals
A29: Shrink Seals

Sheet FD Planner
A1: ASSUMPTIONS | D1: INGREDIENT | E1: DRIED NEEDED (g) | F1: FRESH NEEDED (g)
A2: Number of freeze dryers | B2: 1 | D2: Amaranth | E2: {=IF(D2="","", IFERROR(XLOOKUP(D2, Overview!$A:$A, Overview!$B:$B), 0))} -> 0 | F2: {=IF(D2="","", IFERROR(XLOOKUP(D2, Overview!$A:$A, Overview!$G:$G), 0)/vlookup(D2,'Input Guide'!A:C,3,false))} -> 0
A3: Trays per machine per cycle | B3: 8 | D3: Arugula | E3: {=IF(D3="","", IFERROR(XLOOKUP(D3, Overview!$A:$A, Overview!$B:$B), 0))} -> 0 | F3: {=IF(D3="","", IFERROR(XLOOKUP(D3, Overview!$A:$A, Overview!$G:$G), 0)/vlookup(D3,'Input Guide'!A:C,3,false))} -> 0
A4: Cycle time (hours) | B4: 24 | D4: Basil | E4: {=IF(D4="","", IFERROR(XLOOKUP(D4, Overview!$A:$A, Overview!$B:$B), 0))} -> 0 | F4: {=IF(D4="","", IFERROR(XLOOKUP(D4, Overview!$A:$A, Overview!$G:$G), 0)/vlookup(D4,'Input Guide'!A:C,3,false))} -> 0
A5: Defrost/Clean time per cycle (hours) | B5: 2 | D5: Beet | E5: {=IF(D5="","", IFERROR(XLOOKUP(D5, Overview!$A:$A, Overview!$B:$B), 0))} -> 0 | F5: {=IF(D5="","", IFERROR(XLOOKUP(D5, Overview!$A:$A, Overview!$G:$G), 0)/vlookup(D5,'Input Guide'!A:C,3,false))} -> 0
A6: Operating days per week | B6: 7 | D6: Broccoli | E6: {=IF(D6="","", IFERROR(XLOOKUP(D6, Overview!$A:$A, Overview!$B:$B), 0))} -> 4975.0799 | F6: {=IF(D6="","", IFERROR(XLOOKUP(D6, Overview!$A:$A, Overview!$G:$G), 0)*(vlookup(D6,'Input Guide'!A:C,3,false))*28.35)} -> 49750.939
A7: Operating hours per day | B7: 24 | D7: Cabbage | E7: {=IF(D7="","", IFERROR(XLOOKUP(D7, Overview!$A:$A, Overview!$B:$B), 0))} -> 0 | F7: {=IF(D7="","", IFERROR(XLOOKUP(D7, Overview!$A:$A, Overview!$G:$G), 0)/vlookup(D7,'Input Guide'!A:C,3,false))} -> 0
A8: Days planned this month | B8: 30 | D8: Cantaloupe | E8: {=IF(D8="","", IFERROR(XLOOKUP(D8, Overview!$A:$A, Overview!$B:$B), 0))} -> 0 | F8: {=IF(D8="","", IFERROR(XLOOKUP(D8, Overview!$A:$A, Overview!$G:$G), 0)/vlookup(D8,'Input Guide'!A:C,3,false))} -> 0
A9: Fresh load per FD tray (g) | B9: 300 | D9: Kale | E9: {=IF(D9="","", IFERROR(XLOOKUP(D9, Overview!$A:$A, Overview!$B:$B), 0))} -> 0 | F9: {=IF(D9="","", IFERROR(XLOOKUP(D9, Overview!$A:$A, Overview!$G:$G), 0)/vlookup(D9,'Input Guide'!A:C,3,false))} -> 0
A10: Avg dried yield per FD tray (g) | B10: =B9*B11 -> 30 | D10: Mustard | E10: {=IF(D10="","", IFERROR(XLOOKUP(D10, Overview!$A:$A, Overview!$B:$B), 0))} -> 0 | F10: {=IF(D10="","", IFERROR(XLOOKUP(D10, Overview!$A:$A, Overview!$G:$G), 0)/vlookup(D10,'Input Guide'!A:C,3,false))} -> 0
A11: Dry matter fraction | B11: 0.1 | D11: Pea | E11: {=IF(D11="","", IFERROR(XLOOKUP(D11, Overview!$A:$A, Overview!$B:$B), 0))} -> 0 | F11: {=IF(D11="","", IFERROR(XLOOKUP(D11, Overview!$A:$A, Overview!$G:$G), 0)/vlookup(D11,'Input Guide'!A:C,3,false))} -> 0
D12: Popcorn | E12: {=IF(D12="","", IFERROR(XLOOKUP(D12, Overview!$A:$A, Overview!$B:$B), 0))} -> 0 | F12: {=IF(D12="","", IFERROR(XLOOKUP(D12, Overview!$A:$A, Overview!$G:$G), 0)/vlookup(D12,'Input Guide'!A:C,3,false))} -> 0
A13: CAPACITY | D13: Radish | E13: {=IF(D13="","", IFERROR(XLOOKUP(D13, Overview!$A:$A, Overview!$B:$B), 0))} -> 0 | F13: {=IF(D13="","", IFERROR(XLOOKUP(D13, Overview!$A:$A, Overview!$G:$G), 0)/vlookup(D13,'Input Guide'!A:C,3,false))} -> 0
A14: Trays per cycle | B14: =B2*B3 -> 8 | D14: Sunflower | E14: {=IF(D14="","", IFERROR(XLOOKUP(D14, Overview!$A:$A, Overview!$B:$B), 0))} -> 0 | F14: {=IF(D14="","", IFERROR(XLOOKUP(D14, Overview!$A:$A, Overview!$G:$G), 0)/vlookup(D14,'Input Guide'!A:C,3,false))} -> 0
A15: Hours per cycle | B15: =B4+B5 -> 26 | D15: Upland Cress | E15: {=IF(D15="","", IFERROR(XLOOKUP(D15, Overview!$A:$A, Overview!$B:$B), 0))} -> 0 | F15: {=IF(D15="","", IFERROR(XLOOKUP(D15, Overview!$A:$A, Overview!$G:$G), 0)/vlookup(D15,'Input Guide'!A:C,3,false))} -> 0
A16: Per-cycle fresh capacity (g) | B16: =B9*B14 -> 2400 | D16: Wheatgrass | E16: {=IF(D16="","", IFERROR(XLOOKUP(D16, Overview!$A:$A, Overview!$B:$B), 0))} -> 0 | F16: {=IF(D16="","", IFERROR(XLOOKUP(D16, Overview!$A:$A, Overview!$G:$G), 0)/vlookup(D16,'Input Guide'!A:C,3,false))} -> 0
A17: Total available hours this month | B17: =B7*B8 -> 720 | E17: =SUM(E2:E16) -> 4975.0799 | F17: =SUM(F2:F16) -> 49750.939
A18: Cycles needed | B18: =CEILING(F17/B16,1) -> 21
A19: Hours needed | B19: =B18*B15 -> 546
A20: Max cycles available | B20: =int(B17/B15) -> 27
A21: =IF(F17=0,"No freeze-dry needed", IF(B20 >= B18, "FEASIBLE ✅", "NOT FEASIBLE ❌ — Short by " & TEXT(F17-(B16*B20), "#,##0") & " g fresh (" & CEILING( ((F17/B16)-B20) , 1) & " cycles, ~" & CEILING( ((F17/B16) - B20) *B15 , 1) & " hrs)" )) -> FEASIBLE ✅

Sheet Resource Usage
A1: RESOURCE | B1: UNIT | C1: QTY USED | D1: COST USED | E1: ORDER MORE
A2: Ashwagandha | B2: grams | C2: =VLOOKUP(A2,Overview!$A$6:$B$30,2,false) -> 1014.3141 | D2: =Vlookup(A2,'Input Guide'!$A$2:$B$36,2,false)/(VLOOKUP(A2,'Input Guide'!$A$2:$D$36,4,false)/C2) -> 14.200398
A3: Bladder Wrack | B3: grams | C3: =VLOOKUP(A3,Overview!$A$6:$B$30,2,false) -> 1076.1106 | D3: =Vlookup(A3,'Input Guide'!$A$2:$B$36,2,false)/(VLOOKUP(A3,'Input Guide'!$A$2:$D$36,4,false)/C3) -> 21.522211
A4: Chaga 10:1 | B4: grams | C4: =VLOOKUP(A4,Overview!$A$6:$B$30,2,false) -> 600 | D4: =Vlookup(A4,'Input Guide'!$A$2:$B$36,2,false)/(VLOOKUP(A4,'Input Guide'!$A$2:$D$36,4,false)/C4) -> 15.6
A5: Cordyceps 10:1 | B5: grams | C5: =VLOOKUP(A5,Overview!$A$6:$B$30,2,false) -> 1800 | D5: =Vlookup(A5,'Input Guide'!$A$2:$B$36,2,false)/(VLOOKUP(A5,'Input Guide'!$A$2:$D$36,4,false)/C5) -> 88.2
A6: Lion’s Mane 10:1 | B6: grams | C6: =VLOOKUP(A6,Overview!$A$6:$B$30,2,false) -> 1641.0988 | D6: =Vlookup(A6,'Input Guide'!$A$2:$B$36,2,false)/(VLOOKUP(A6,'Input Guide'!$A$2:$D$36,4,false)/C6) -> 66.464501
A7: Purple Irish sea moss | B7: grams | C7: =VLOOKUP(A7,Overview!$A$6:$B$30,2,false) -> 1076.1106 | D7: =Vlookup(A7,'Input Guide'!$A$2:$B$36,2,false)/(VLOOKUP(A7,'Input Guide'!$A$2:$D$36,4,false)/C7) -> 113.87614
A8: Reishi 10:1 | B8: grams | C8: =VLOOKUP(A8,Overview!$A$6:$B$30,2,false) -> 1641.0988 | D8: =Vlookup(A8,'Input Guide'!$A$2:$B$36,2,false)/(VLOOKUP(A8,'Input Guide'!$A$2:$D$36,4,false)/C8) -> 54.15626
A9: Bottles | B9: units | C9: =VLOOKUP(A9,Overview!$D$6:$E$23,2,false) -> 501 | D9: =C9*VLOOKUP(A9,'Input Guide'!$A$2:$B$40,2,false) -> 230.46
A10: Capsules | B10: units | C10: =VLOOKUP(A10,Overview!$D$6:$E$23,2,false) -> 30060 | D10: =C10*VLOOKUP(A10,'Input Guide'!$A$2:$B$40,2,false) -> 462.924
A11: Labels | B11: units | C11: =VLOOKUP(A11,Overview!$D$6:$E$23,2,false) -> 501 | D11: =C11*VLOOKUP(A11,'Input Guide'!$A$2:$B$40,2,false) -> 5.01
A12: Lids | B12: units | C12: =VLOOKUP(A12,Overview!$D$6:$E$23,2,false) -> 501 | D12: =C12*VLOOKUP(A12,'Input Guide'!$A$2:$B$40,2,false) -> 55.11
A13: Seals | B13: units | C13: =VLOOKUP(A13,Overview!$D$6:$E$23,2,false) -> 501 | D13: =C13*VLOOKUP(A13,'Input Guide'!$A$2:$B$40,2,false) -> 0
A14: Shrink Seals | B14: units | C14: =VLOOKUP(A14,Overview!$D$6:$E$23,2,false) -> 501 | D14: =C14*VLOOKUP(A14,'Input Guide'!$A$2:$B$40,2,false) -> 0

Sheet Production Actuals
A1: PRODUCT | B1: BOTTLES PLANNED | C1: ACTUAL BOTTLES | D1: VARIANCE BOTTLES | E1: CAPS PLANNED | F1: EXCESS CAPS | G1: ACTUAL CAPS | H1: VARIANCE CAPS | J1: RESOURCE | K1: TRAYS PLANNED | L1: ACTUAL TRAYS | M1: VARIANCE
A2: Complete102+ | B2: =VLOOKUP(A2,'Products (Demand)'!$A$2:$E$29,5,false) -> 147 | D2: =B2-C2 -> 147 | E2: =B2*VLOOKUP(A2,'Products (Demand)'!$A$2:$C$29,3,false) -> 8820 | G2: =C2*60+F2 -> 0 | H2: =E2-G2 -> 8820 | J2: Amaranth | K2: =VLOOKUP(J2,Overview!$A$6:$H$28,8,false) -> 0 | M2: =K2-L2 -> 0
A3: Mushroom | B3: =VLOOKUP(A3,'Products (Demand)'!$A$2:$E$29,5,false) -> 200 | D3: =B3-C3 -> 200 | E3: =B3*VLOOKUP(A3,'Products (Demand)'!$A$2:$C$29,3,false) -> 12000 | G3: =C3*60+F3 -> 0 | H3: =E3-G3 -> 12000 | J3: Arugula | K3: =VLOOKUP(J3,Overview!$A$6:$H$28,8,false) -> 0 | M3: =K3-L3 -> 0
A4: Broccoli | B4: =VLOOKUP(A4,'Products (Demand)'!$A$2:$E$29,5,false) -> 154 | D4: =B4-C4 -> 154 | E4: =B4*VLOOKUP(A4,'Products (Demand)'!$A$2:$C$29,3,false) -> 9240 | G4: =C4*60+F4 -> 0 | H4: =E4-G4 -> 9240 | J4: Basil | K4: =VLOOKUP(J4,Overview!$A$6:$H$28,8,false) -> 0 | M4: =K4-L4 -> 0
J5: Beet | K5: =VLOOKUP(J5,Overview!$A$6:$H$28,8,false) -> 0 | M5: =K5-L5 -> 0
J6: Broccoli | K6: =VLOOKUP(J6,Overview!$A$6:$H$28,8,false) -> 192 | M6: =K6-L6 -> 192
J7: Cabbage | K7: =VLOOKUP(J7,Overview!$A$6:$H$28,8,false) -> 0 | M7: =K7-L7 -> 0
J8: Cantaloupe | K8: =VLOOKUP(J8,Overview!$A$6:$H$28,8,false) -> 0 | M8: =K8-L8 -> 0
J9: Kale | K9: =VLOOKUP(J9,Overview!$A$6:$H$28,8,false) -> 0 | M9: =K9-L9 -> 0
J10: Mustard | K10: =VLOOKUP(J10,Overview!$A$6:$H$28,8,false) -> 0 | M10: =K10-L10 -> 0
J11: Pea | K11: =VLOOKUP(J11,Overview!$A$6:$H$28,8,false) -> 0 | M11: =K11-L11 -> 0
J12: Popcorn | K12: =VLOOKUP(J12,Overview!$A$6:$H$28,8,false) -> 0 | M12: =K12-L12 -> 0
J13: Radish | K13: =VLOOKUP(J13,Overview!$A$6:$H$28,8,false) -> 0 | M13: =K13-L13 -> 0
J14: Sunflower | K14: =VLOOKUP(J14,Overview!$A$6:$H$28,8,false) -> 0 | M14: =K14-L14 -> 0
J15: Upland Cress | K15: =VLOOKUP(J15,Overview!$A$6:$H$28,8,false) -> 0 | M15: =K15-L15 -> 0
J16: Wheatgrass | K16: =VLOOKUP(J16,Overview!$A$6:$H$28,8,false) -> 0 | M16: =K16-L16 -> 0
